<?xml version='1.0'?>
<sdf version='1.7'>
  <model name='pico'>
    <pose>0 0 -1 0 0 0</pose>
    <link name="hull">
    	<pose>0 0 0 0 0 0</pose>
      <inertial>
        <mass>1.360776</mass>
        <inertia>
          <ixx>1.42222E-03</ixx>
          <ixy>0</ixy>
          <ixz>0</ixz>
          <iyy>6.703089E-03</iyy>
          <iyz>0</iyz>
          <izz>6.703089E-03</izz>
        </inertia>
      </inertial>

      <visual name='hull_visual'>
        <geometry>
            <mesh><uri>model://pico/pico.dae</uri></mesh> 
        </geometry>    
      </visual>

      <collision name='hull_collision'>
        <pose>0 0 0 0 1.5707963267948966 0</pose>
        <geometry>
          <cylinder>
            <radius>4.572000E-02</radius>
            <length>2.2887000E-01</length>
          </cylinder>
        </geometry>
      </collision>

      <sensor type="imu" name="imu_sensor">
        <always_on>1</always_on>
        <update_rate>200</update_rate>
      </sensor>

      <sensor type="camera" name="camera_sensor">
        <always_on>1</always_on>
        <update_rate>30</update_rate>
        <visualize>true</visualize> <!--See the camera cone in the GUI-->
        <pose>1.017E-1 0 0 0 0 0</pose>
        <camera>
          <horizontal_fov>1.047</horizontal_fov>
          <image>
            <width>320</width>
            <height>240</height>
          </image>
          <clip>
            <near>0.001</near>
            <far>100</far>
          </clip>
        </camera>
      </sensor>

      


    </link>

    <link name="thruster_1">
      <pose>0.082 -0.108 0 0 0 0</pose>
      <inertial>
        <pose>0 0 0 0 0 0</pose>
        <mass>2.599998E-02</mass>
        <inertia>
          <ixx>2.738659E-06</ixx>
          <ixy>0</ixy>
          <ixz>0</ixz>
          <iyy>2.738659E-06</iyy>
          <iyz>0</iyz>
          <izz>2.547998E-06</izz>
        </inertia>
      </inertial>
        
      <!--
      <visual name="thruster_1_visual">
        <pose>0 0 0 0 0 0</pose>
        <geometry>
          <cylinder>
            <radius>1.400000E-02</radius>
            <length>2.599995E-02</length>
          </cylinder>
        </geometry>
      </visual>
      -->

      <collision name="thruster_1_collision">
        <pose>0 0 0 0 0 0</pose>
        <geometry>
          <cylinder>
            <radius>1.400000E-02</radius>
            <length>2.599995E-02</length>
          </cylinder>
        </geometry>
      </collision>
    </link>

    <link name="thruster_2">
      <pose>0 -0.071 0.048 0 0 0</pose>
      <inertial>
        <pose>0 0 0 0 1.5707963267948966 0</pose>
        <mass>2.599998E-02</mass>
        <inertia>
          <ixx>2.738659E-06</ixx>
          <ixy>0</ixy>
          <ixz>0</ixz>
          <iyy>2.738659E-06</iyy>
          <iyz>0</iyz>
          <izz>2.547998E-06</izz>
        </inertia>
      </inertial>
      
      <!-- 
      <visual name="thruster_2_visual">
        <pose>0 0 0 0 1.5707963267948966 0</pose>
        <geometry>
          <cylinder>
            <radius>1.400000E-02</radius>
            <length>2.599995E-02</length>
          </cylinder>
        </geometry>
      </visual>
      -->

      <collision name="thruster_2_collision">
        <pose>0 0 0 0 1.5707963267948966 0</pose>
        <geometry>
          <cylinder>
            <radius>1.400000E-02</radius>
            <length>2.599995E-02</length>
          </cylinder>
        </geometry>
      </collision>
    </link>

    <link name="thruster_3">
      <pose>-0.082 -0.108 0 0 0 0</pose>
      <inertial>
        <pose>0 0 0 0 0 0</pose>
        <mass>2.599998E-02</mass>
        <inertia>
          <ixx>2.738659E-06</ixx>
          <ixy>0</ixy>
          <ixz>0</ixz>
          <iyy>2.738659E-06</iyy>
          <iyz>0</iyz>
          <izz>2.547998E-06</izz>
        </inertia>
      </inertial>
      
      <!--  
      <visual name="thruster_3_visual">
        <pose>0 0 0 0 0 0</pose>
        <geometry>
          <cylinder>
            <radius>1.400000E-02</radius>
            <length>2.599995E-02</length>
          </cylinder>
        </geometry>
      </visual>
      -->

      <collision name="thruster_3_collision">
        <pose>0 0 0 0 0 0</pose>
        <geometry>
          <cylinder>
            <radius>1.400000E-02</radius>
            <length>2.599995E-02</length>
          </cylinder>
        </geometry>
      </collision>
    </link>

    <link name="thruster_4">
      <pose>-0.082 0.108 0 0 0 0</pose>
      <inertial>
        <pose>0 0 0 0 0 0</pose>
        <mass>2.599998E-02</mass>
        <inertia>
          <ixx>2.738659E-06</ixx>
          <ixy>0</ixy>
          <ixz>0</ixz>
          <iyy>2.738659E-06</iyy>
          <iyz>0</iyz>
          <izz>2.547998E-06</izz>
        </inertia>
      </inertial>
     
      <!--
      <visual name="thruster_4_visual">
        <pose>0 0 0 0 0 0</pose>
        <geometry>
          <cylinder>
            <radius>1.400000E-02</radius>
            <length>2.599995E-02</length>
          </cylinder>
        </geometry>
      </visual>
      -->

      <collision name="thruster_4_collision">
        <pose>0 0 0 0 0 0</pose>
        <geometry>
          <cylinder>
            <radius>1.400000E-02</radius>
            <length>2.599995E-02</length>
          </cylinder>
        </geometry>
      </collision>
    </link>

    <link name="thruster_5">
      <pose>0 0.071 0.048 0 0 0</pose>
      <inertial>
        <pose>0 0 0 0 1.5707963267948966 0</pose>
        <mass>2.599998E-02</mass>
        <inertia>
          <ixx>2.738659E-06</ixx>
          <ixy>0</ixy>
          <ixz>0</ixz>
          <iyy>2.738659E-06</iyy>
          <iyz>0</iyz>
          <izz>2.547998E-06</izz>
        </inertia>
      </inertial>
        
      <!--
      <visual name="thruster_5_visual">
        <pose>0 0 0 0 1.5707963267948966 0</pose>
        <geometry>
          <cylinder>
            <radius>1.400000E-02</radius>
            <length>2.599995E-02</length>
          </cylinder>
        </geometry>
      </visual>
      -->

      <collision name="thruster_5_collision">
        <pose>0 0 0 0 1.5707963267948966 0</pose>
        <geometry>
          <cylinder>
            <radius>1.400000E-02</radius>
            <length>2.599995E-02</length>
          </cylinder>
        </geometry>
      </collision>
    </link>

    <link name="thruster_6">
      <pose>0.082 0.108 0 0 0 0</pose>
      <inertial>
        <pose>0 0 0 0 0 0</pose>
        <mass>2.599998E-02</mass>
        <inertia>
          <ixx>2.738659E-06</ixx>
          <ixy>0</ixy>
          <ixz>0</ixz>
          <iyy>2.738659E-06</iyy>
          <iyz>0</iyz>
          <izz>2.547998E-06</izz>
        </inertia>
      </inertial>

      <!--
      <visual name="thruster_6_visual">
        <pose>0 0 0 0 0 0</pose>
        <geometry>
          <cylinder>
            <radius>1.400000E-02</radius>
            <length>2.599995E-02</length>
          </cylinder>
        </geometry>
      </visual>
      -->

      <collision name="thruster_6_collision">
        <pose>0 0 0 0 0 0</pose>
        <geometry>
          <cylinder>
            <radius>1.400000E-02</radius>
            <length>2.599995E-02</length>
          </cylinder>
        </geometry>
      </collision>
    </link>

    <joint name="thruster_1_joint" type="revolute">
      <child>thruster_1</child>
      <parent>hull</parent>
      <axis>
        <xyz>0 0 1</xyz>
        <limit>
          <lower>-1e+16</lower>
          <upper>1e+16</upper>
        </limit>
      </axis>
    </joint>

    <joint name="thruster_2_joint" type="revolute">
      <child>thruster_2</child>
      <parent>hull</parent>
      <axis>
        <xyz>1 0 0</xyz>
        <limit>
          <lower>-1e+16</lower>
          <upper>1e+16</upper>
        </limit>
      </axis>
    </joint>

    <joint name="thruster_3_joint" type="revolute">
      <child>thruster_3</child>
      <parent>hull</parent>
      <axis>
        <xyz>0 0 1</xyz>
        <limit>
          <lower>-1e+16</lower>
          <upper>1e+16</upper>
        </limit>
      </axis>
    </joint>

    <joint name="thruster_4_joint" type="revolute">
      <child>thruster_4</child>
      <parent>hull</parent>
      <axis>
        <xyz>0 0 1</xyz>
        <limit>
          <lower>-1e+16</lower>
          <upper>1e+16</upper>
        </limit>
      </axis>
    </joint>

    <joint name="thruster_5_joint" type="revolute">
      <child>thruster_5</child>
      <parent>hull</parent>
      <axis>
        <xyz>1 0 0</xyz>
        <limit>
          <lower>-1e+16</lower>
          <upper>1e+16</upper>
        </limit>
      </axis>
    </joint>

    <joint name="thruster_6_joint" type="revolute">
      <child>thruster_6</child>
      <parent>hull</parent>
      <axis>
        <xyz>0 0 1</xyz>
        <limit>
          <lower>-1e+16</lower>
          <upper>1e+16</upper>
        </limit>
      </axis>
    </joint>

    <!--Hydrodynamics-->
    <plugin name="BuoyancyPlugin" filename="libBuoyancyPlugin.so">
      <fluid_density>1000</fluid_density>
      <link name="hull">
        <center_of_volume>0 0 0</center_of_volume>
        <volume>0.25e-02</volume>
      </link>
    </plugin>
   
    <plugin name="ThrusterPlugin" filename="libThrusterPlugin.so"/>

    <plugin name="DepthSensorPlugin" filename="libDepthSensorPlugin.so"/>

  </model>
</sdf>
